Workbook

Sheet Hrs. Summary
B2: Service Hours - 2025 | H2: BUSES PER ROUTE | O2: 2025
B4: Total Annual Service Hours | E4: =E21+E39+E56+T18 -> #REF!
B6: Weekday Service | O6: Total number of weekdays | S6: Holiday | T6: Hours
I7: Peak | J7: Off Peak | O7: 252 | S7: New Years Day | T7: 0
B8: ROUTE | C8: Service Hours/Weekday | D8: Service Hours /Year | E8: Weekday Difference From Previous Master | H8: ROUTE | I8: Buses | O8: Total number of Saturdays | S8: Family Day | T8: =$E$57 -> #REF!
O9: 52 | S9: Easter Sunday | T9: 0
B10: 400 | C10: ='400'!Q29 -> 23.366667 | D10: =C10*$O$7 -> 5888.4 | E10: =C10-'[1]Hrs. Summary'!C8 -> #REF! | H10: 400 | I10: 2 | J10: 0 | O10: Total number of Sundays | S10: Victoria Day | T10: 0
B11: 100 | C11: ='100'!U43 -> 30.533333 | D11: =C11*$O$7 -> 7694.4 | E11: =C11-'[1]Hrs. Summary'!C9 -> #REF! | H11: 100 | I11: 2 | J11: 2 | O11: 52 | S11: Canada Day | T11: =$E$57 -> #REF!
B12: 101 | C12: ='101'!Q42 -> 29.683333 | D12: =C12*$O$7 -> 7480.2 | E12: =C12-'[1]Hrs. Summary'!C10 -> #REF! | H12: 101 | I12: 2 | J12: 2 | O12: Total number of Serviced Holiday | S12: Civic Holiday | T12: =$E$57 -> #REF!
B13: 2 | C13: ='2'!W39 -> 48.283333 | D13: =C13*$O$7 -> 12167.4 | E13: =C13-'[1]Hrs. Summary'!C11 -> #REF! | H13: 2 | I13: 2 | J13: 1 | O13: 6 | S13: Labour Day | T13: =$E$57 -> #REF!
B14: 7 | C14: ='7'!AD39 -> 64.133333 | D14: =C14*$O$7 -> 16161.6 | E14: =C14-'[1]Hrs. Summary'!C12 -> #REF! | H14: 7 | I14: 4 | J14: 2 | O14: Total number of Un-serviced Holiday | S14: Thanksgiving | T14: 0
B15: 8A | C15: ='8A'!AH43 -> 83.1 | D15: =C15*$O$7 -> 20941.2 | E15: =C15-'[1]Hrs. Summary'!C13 -> #REF! | H15: 8A | I15: 5 | J15: 2.5 | O15: 5 | S15: Christmas Day | T15: 0
B16: 8B | C16: ='8B'!AI42 -> 79.433333 | D16: =C16*$O$7 -> 20017.2 | E16: =C16-'[1]Hrs. Summary'!C14 -> #REF! | H16: 8B | I16: 5 | J16: 2.5 | P16: Total Days | S16: Boxing Day | T16: 263
B17: 10 | C17: ='10'!Q40 -> 34.833333 | D17: =C17*$O$7 -> 8778 | E17: =C17-'[1]Hrs. Summary'!C15 -> #REF! | H17: 10 | I17: 2 | J17: 1 | P17: =O7+O9+O11+O13+O15 -> 367 | S17: New Years Eve | T17: 68
B18: 11 | C18: =#REF! -> #REF! | D18: =C18*$O$7 -> #REF! | E18: =C18-'[1]Hrs. Summary'!C16 -> #REF! | F18: just routes | H18: 11 | I18: 2 | J18: 1 | S18: Total | T18: =SUM(T7:T17) -> #REF!
B19: 12 | C19: ='12'!AH39 -> 69.483333 | D19: =C19*$O$7 -> 17509.8 | E19: =C19-'[1]Hrs. Summary'!C17 -> #REF! | F19: =SUM(C10:C19) -> #REF! | H19: 12 | I19: 4 | J19: 2
B20: TOD | C20: =ToD!CI11 -> 98.25 | D20: =C20*$O$7 -> 24759 | E20: =C20-'[1]Hrs. Summary'!C18 -> #REF! | H20: TOD | I20: 6 | J20: 2
B21: Total Trips | C21: TOTAL HOURS PER YEAR | E21: =SUM(D10:D20) -> #REF! | I21: =SUM(I10:I20) -> 36 | J21: =SUM(J10:J20) -> 18
C22: Total Hours per Day | E22: =SUM(C10:C20) -> #REF! | O22: 2025 Budgeting
P24: Previous Master (Annualized)
B25: Saturday Service | Q25: Rate | R25: Hours | S25: Cost
C26: Service Hours/Weekday | D26: Service Hours /Year | E26: Saturday Difference From Previous Master | I26: Peak | J26: Off Peak | P26: ToD Hours | Q26: 55.65 | R26: ='[1]Hrs. Summary'!$D$18+'[1]Hrs. Summary'!$D$38+'[1]Hrs. Summary'!$D$55 -> #REF! | S26: =R26*Q26 -> #REF!
B27: ROUTE | H27: ROUTE | I27: Buses | P27: Fixed Hours | Q27: 65 | R27: =SUM('[1]Hrs. Summary'!$D$8:$D$17,'[1]Hrs. Summary'!$D$28:$D$37,'[1]Hrs. Summary'!$D$45:$D$54) -> #REF! | S27: =R27*Q27 -> #REF!
B28: 400 | C28: ='400'!Q55 -> 19.366667 | D28: =C28*$O$9 -> 1007.0667 | E28: =C28-'[1]Hrs. Summary'!C28 -> #REF! | H28: 400 | I28: 2 | J28: 0 | P28: Annual Operational Costs | S28: =SUM(S26:S27) -> #REF!
B29: 100 | C29: ='100'!U85 -> 28.966667 | D29: =C29*$O$9 -> 1506.2667 | E29: =C29-'[1]Hrs. Summary'!C29 -> #REF! | H29: 100 | I29: 2 | J29: 2
B30: 101 | C30: ='101'!Q84 -> 28.7 | D30: =C30*$O$9 -> 1492.4 | E30: =C30-'[1]Hrs. Summary'!C30 -> #REF! | H30: 101 | I30: 2 | J30: 2 | P30: Current Master (Annualized)
B31: 2 | C31: ='2'!W79 -> 45.35 | D31: =C31*$O$9 -> 2358.2 | E31: =C31-'[1]Hrs. Summary'!C31 -> #REF! | H31: 2 | I31: 2 | J31: 1 | Q31: Rate | R31: Hours | S31: Cost
B32: 7 | C32: ='7'!AD77 -> 59.9 | D32: =C32*$O$9 -> 3114.8 | E32: =C32-'[1]Hrs. Summary'!C32 -> #REF! | H32: 7 | I32: 4 | J32: 2 | P32: ToD Hours | Q32: 55.65 | R32: =D20+D38+D55+T18 -> #REF! | S32: =R32*Q32 -> #REF!
B33: 8A | C33: ='8A'!AH84 -> 73.483333 | D33: =C33*$O$9 -> 3821.1333 | E33: =C33-'[1]Hrs. Summary'!C33 -> #REF! | H33: 8A | I33: 5 | J33: 2.5 | P33: Fixed Hours | Q33: 65 | R33: =SUM(D10:D19,D28:D37,D45:D54) -> #REF! | S33: =R33*Q33 -> #REF!
B34: 8B | C34: ='8B'!AI83 -> 71.766667 | D34: =C34*$O$9 -> 3731.8667 | E34: =C34-'[1]Hrs. Summary'!C34 -> #REF! | H34: 8B | I34: 5 | J34: 2.5 | P34: Annual Operational Costs | S34: =SUM(S32:S33) -> #REF!
B35: 10 | C35: ='10'!Q78 -> 31.833333 | D35: =C35*$O$9 -> 1655.3333 | E35: =C35-'[1]Hrs. Summary'!C35 -> #REF! | H35: 10 | I35: 2 | J35: 1 | R35: Net | S35: =S34-S28 -> #REF!
B36: 11 | C36: =#REF! -> #REF! | D36: =C36*$O$9 -> #REF! | E36: =C36-'[1]Hrs. Summary'!C36 -> #REF! | F36: just routes | H36: 11 | I36: 2 | J36: 1
B37: 12 | C37: ='12'!AH79 -> 65.883333 | D37: =C37*$O$9 -> 3425.9333 | E37: =C37-'[1]Hrs. Summary'!C37 -> #REF! | F37: =SUM(C28:C37) -> #REF! | H37: 12 | I37: 4 | J37: 2
B38: TOD | C38: =ToD!CI20 -> 77.25 | D38: =C38*$O$9 -> 4017 | E38: =C38-'[1]Hrs. Summary'!C38 -> #REF! | H38: TOD | I38: 5 | J38: 2
B39: Total Trips | C39: TOTAL HOURS PER YEAR = | E39: =SUM(D28:D38) -> #REF! | I39: =SUM(I28:I38) -> 35 | J39: =SUM(J28:J38) -> 18
C40: Total Hours per Day | E40: =SUM(C28:C38) -> #REF!
B42: Sunday + Holiday Service
C43: Service Hours/Weekday | D43: Service Hours /Year | E43: Sunday Difference From Previous Master | I43: Peak | J43: Off Peak
B44: ROUTE | H44: ROUTE | I44: Buses
B45: 400 | C45: 0 | D45: =C45*($O$11) -> 0 | E45: =C45-'[1]Hrs. Summary'!C45 -> #REF! | H45: 400 | I45: 0 | J45: 0
...

Sheet 400
A1: Weekday | C1: 400 North | I1: 400 South
G2: Arrive | I2: DEPART | M2: Arrive | O2: DEPART
B3: Stop Name | C3: Park Place | D3: Veteran's at Essa | E3: Rose at Highway 400 | F3: Georgian at Governors | G3: RVH | H3: R | I3: RVH | J3: Georgian College | K3: Bayfield at Highway 400 | L3: Veteran's at Essa | M3: Park Place | N3: R | O3: Park Place
B4: Stop ID | C4: 777 | D4: 662 | E4: 63 | F4: 329 | G4: 612 | I4: 612 | J4: 330 | K4: 62 | L4: 847 | M4: 777 | O4: 777 | P4: Travel Time | Q4: Cycle Time | R4: R | S4: R Ratio | T4: Frequency
B5: Morning | I5: 0.28472222 | J5: 0.2875 | K5: 0.29166667 | L5: 0.29722222 | M5: 0.30208333 | N5: 5 | O5: 0.30555556 | P5: =Q5-R5 -> 25 | Q5: =(O5-I5)*1440 -> 30 | R5: =N5+H5 -> 5 | S5: =R5/P5 -> 0.2
B6: Morning | C6: 0.28472222 | D6: 0.28888889 | E6: 0.29583333 | F6: 0.29861111 | G6: 0.3 | H6: 6 | I6: 0.30416667 | J6: 0.30694444 | K6: 0.31111111 | L6: 0.31666667 | M6: 0.32152778 | N6: 7 | O6: 0.32638889 | P6: =Q6-R6 -> 47 | Q6: =(O6-C6)*1440 -> 60 | R6: =N6+H6 -> 13 | S6: =R6/P6 -> 0.27659574 | T6: =(O6-O5)*1440 -> 30
B7: Morning | C7: 0.30555556 | D7: 0.30972222 | E7: 0.31666667 | F7: 0.31944444 | G7: 0.32083333 | H7: 6 | I7: 0.325 | J7: 0.32777778 | K7: 0.33194444 | L7: 0.3375 | M7: 0.34236111 | N7: 7 | O7: 0.34722222 | P7: =Q7-R7 -> 47 | Q7: =(O7-C7)*1440 -> 60 | R7: =N7+H7 -> 13 | S7: =R7/P7 -> 0.27659574 | T7: =(O7-O6)*1440 -> 30
B8: Morning | C8: 0.32638889 | D8: 0.33055556 | E8: 0.3375 | F8: 0.34027778 | G8: 0.34166667 | H8: 9 | I8: 0.34791667 | J8: 0.35069444 | K8: 0.35486111 | L8: 0.36041667 | M8: 0.36527778 | N8: 4 | O8: 0.36805556 | P8: =Q8-R8 -> 47 | Q8: =(O8-C8)*1440 -> 60 | R8: =N8+H8 -> 13 | S8: =R8/P8 -> 0.27659574 | T8: =(O8-O7)*1440 -> 30
B9: Morning | C9: 0.34722222 | D9: 0.35138889 | E9: 0.35833333 | F9: 0.36111111 | G9: 0.3625 | H9: 9 | I9: 0.36875 | J9: 0.37152778 | K9: 0.37569444 | L9: 0.38125 | M9: 0.38611111 | N9: 4 | O9: 0.38888889 | P9: =Q9-R9 -> 47 | Q9: =(O9-C9)*1440 -> 60 | R9: =N9+H9 -> 13 | S9: =R9/P9 -> 0.27659574 | T9: =(O9-O8)*1440 -> 30
B10: Morning | C10: 0.36805556 | D10: 0.37222222 | E10: 0.37916667 | F10: 0.38194444 | G10: 0.38333333 | H10: 9 | I10: 0.38958333 | J10: 0.39236111 | K10: 0.39652778 | L10: 0.40208333 | M10: 0.40694444 | N10: 4 | O10: 0.40972222 | P10: =Q10-R10 -> 47 | Q10: =(O10-C10)*1440 -> 60 | R10: =N10+H10 -> 13 | S10: =R10/P10 -> 0.27659574 | T10: =(O10-O9)*1440 -> 30
B11: Morning | C11: 0.38888889 | D11: 0.39305556 | E11: 0.4 | F11: 0.40277778 | G11: 0.40416667 | H11: 9 | I11: 0.41041667 | J11: 0.41319444 | K11: 0.41736111 | L11: 0.42291667 | M11: 0.42777778 | N11: 4 | O11: 0.43055556 | P11: =Q11-R11 -> 47 | Q11: =(O11-C11)*1440 -> 60 | R11: =N11+H11 -> 13 | S11: =R11/P11 -> 0.27659574 | T11: =(O11-O10)*1440 -> 30
B12: Morning | C12: 0.40972222 | D12: 0.41388889 | E12: 0.42083333 | F12: 0.42361111 | G12: 0.425 | H12: 9 | I12: 0.43125 | J12: 0.43402778 | K12: 0.43819444 | L12: 0.44375 | M12: 0.44861111 | N12: 4 | O12: 0.45138889 | P12: =Q12-R12 -> 47 | Q12: =(O12-C12)*1440 -> 60 | R12: =N12+H12 -> 13 | S12: =R12/P12 -> 0.27659574 | T12: =(O12-O11)*1440 -> 30
B13: Morning | C13: 0.43055556 | D13: 0.43472222 | E13: 0.44166667 | F13: 0.44444444 | G13: 0.44583333 | H13: 9 | I13: 0.45208333 | J13: 0.45486111 | K13: 0.45902778 | L13: 0.46458333 | M13: 0.46944444 | N13: 4 | O13: 0.47222222 | P13: =Q13-R13 -> 47 | Q13: =(O13-C13)*1440 -> 60 | R13: =N13+H13 -> 13 | S13: =R13/P13 -> 0.27659574 | T13: =(O13-O12)*1440 -> 30
B14: Morning | C14: 0.45138889 | D14: 0.45555556 | E14: 0.4625 | F14: 0.46527778 | G14: 0.46666667 | H14: 8 | I14: 0.47222222 | J14: 0.475 | K14: 0.47916667 | L14: 0.48472222 | M14: 0.48958333 | N14: 5 | O14: 0.49305556 | P14: =Q14-R14 -> 47 | Q14: =(O14-C14)*1440 -> 60 | R14: =N14+H14 -> 13 | S14: =R14/P14 -> 0.27659574 | T14: =(O14-O13)*1440 -> 30
B15: Midday | C15: 0.47222222 | D15: 0.47708333 | E15: 0.48472222 | F15: 0.4875 | G15: 0.48888889 | H15: 6 | I15: 0.49305556 | J15: 0.49583333 | K15: 0.5 | L15: 0.50625 | M15: 0.51111111 | N15: 4 | O15: 0.51388889 | P15: =Q15-R15 -> 50 | Q15: =(O15-C15)*1440 -> 60 | R15: =N15+H15 -> 10 | S15: =R15/P15 -> 0.2 | T15: =(O15-O14)*1440 -> 30
B16: Midday | C16: 0.49305556 | D16: 0.49791667 | E16: 0.50555556 | F16: 0.50833333 | G16: 0.50972222 | H16: 6 | I16: 0.51388889 | J16: 0.51666667 | K16: 0.52083333 | L16: 0.52708333 | M16: 0.53194444 | N16: 4 | O16: 0.53472222 | P16: =Q16-R16 -> 50 | Q16: =(O16-C16)*1440 -> 60 | R16: =N16+H16 -> 10 | S16: =R16/P16 -> 0.2 | T16: =(O16-O15)*1440 -> 30
B17: Midday | C17: 0.51388889 | D17: 0.51875 | E17: 0.52638889 | F17: 0.52916667 | G17: 0.53055556 | H17: 6 | I17: 0.53472222 | J17: 0.5375 | K17: 0.54166667 | L17: 0.54791667 | M17: 0.55277778 | N17: 4 | O17: 0.55555556 | P17: =Q17-R17 -> 50 | Q17: =(O17-C17)*1440 -> 60 | R17: =N17+H17 -> 10 | S17: =R17/P17 -> 0.2 | T17: =(O17-O16)*1440 -> 30
... B26: Evening | C26: 0.70138889 | D26: 0.70694444 | E26: 0.71388889 | F26: 0.71666667 | G26: 0.71805556 | H26: 6 | I26: 0.72222222 | J26: 0.725 | K26: 0.72916667 | L26: 0.73541667 | M26: 0.74027778 | N26: 4 | O26: 0.74305556 | P26: =Q26-R26 -> 50 | Q26: =(O26-C26)*1440 -> 60 | R26: =N26+H26 -> 10 | S26: =R26/P26 -> 0.2 | T26: =(O26-O25)*1440 -> 30
B27: Evening | C27: 0.72222222 | D27: 0.72777778 | E27: 0.73472222 | F27: 0.7375 | G27: 0.73888889 | H27: 6 | I27: 0.74305556 | J27: 0.74583333 | K27: 0.75 | L27: 0.75625 | M27: 0.76111111 | N27: 0 | O27: Block Ends | P27: =Q27-R27 -> 50 | Q27: =(M27-C27)*1440 -> 56 | R27: =N27+H27 -> 6 | S27: =R27/P27 -> 0.12 | T27: =(M27-M26)*1440 -> 30
B28: Evening | C28: 0.74305556 | D28: 0.74861111 | E28: 0.75555556 | F28: 0.75833333 | G28: 0.75972222 | H28: 6 | I28: 0.76388889 | J28: 0.76666667 | K28: 0.77083333 | L28: 0.77708333 | M28: 0.78194444 | N28: 0 | O28: Block Ends | P28: =Q28-R28 -> 50 | Q28: =(M28-C28)*1440 -> 56 | R28: =N28+H28 -> 6 | S28: =R28/P28 -> 0.12 | T28: =(M28-M27)*1440 -> 30
M29: Service Hours | P29: =SUM(P5:P28)/60 -> 19.133333 | Q29: =SUM(Q5:Q28)/60 -> 23.366667 | R29: =SUM(R5:R28)/60 -> 4.2333333
A31: Saturday | C31: 400 North | I31: 400 South
G32: Arrive | I32: DEPART | M32: Arrive | O32: DEPART
B33: Stop Name | C33: Park Place | D33: Veteran's at Essa | E33: Rose at Highway 400 | F33: Georgian at Governors | G33: RVH | H33: R | I33: RVH | J33: Georgian College | K33: Bayfield at Highway 400 | L33: Veteran's at Essa | M33: Park Place | N33: R | O33: Park Place
B34: Stop ID | C34: 777 | D34: 662 | E34: 63 | F34: 329 | G34: 612 | I34: 612 | J34: 330 | K34: 62 | L34: 847 | M34: 777 | O34: 777 | P34: Travel Time | Q34: Cycle Time | R34: R | S34: R Ratio | T34: Frequency
B35: Morning | I35: 0.36805556 | J35: 0.37083333 | K35: 0.375 | L35: 0.38055556 | M35: 0.38541667 | N35: 5 | O35: 0.38888889 | P35: =Q35-R35 -> 25 | Q35: =(O35-I35)*1440 -> 30 | R35: =N35+H35 -> 5 | S35: =R35/P35 -> 0.2
B36: Morning | C36: 0.36805556 | D36: 0.37222222 | E36: 0.37916667 | F36: 0.38194444 | G36: 0.38333333 | H36: 9 | I36: 0.38958333 | J36: 0.39236111 | K36: 0.39652778 | L36: 0.40208333 | M36: 0.40694444 | N36: 4 | O36: 0.40972222 | P36: =Q36-R36 -> 47 | Q36: =(O36-C36)*1440 -> 60 | R36: =N36+H36 -> 13 | S36: =R36/P36 -> 0.27659574 | T36: =(O36-O35)*1440 -> 30
B37: Morning | C37: 0.38888889 | D37: 0.39305556 | E37: 0.4 | F37: 0.40277778 | G37: 0.40416667 | H37: 9 | I37: 0.41041667 | J37: 0.41319444 | K37: 0.41736111 | L37: 0.42291667 | M37: 0.42777778 | N37: 4 | O37: 0.43055556 | P37: =Q37-R37 -> 47 | Q37: =(O37-C37)*1440 -> 60 | R37: =N37+H37 -> 13 | S37: =R37/P37 -> 0.27659574 | T37: =(O37-O36)*1440 -> 30
B38: Morning | C38: 0.40972222 | D38: 0.41388889 | E38: 0.42083333 | F38: 0.42361111 | G38: 0.425 | H38: 9 | I38: 0.43125 | J38: 0.43402778 | K38: 0.43819444 | L38: 0.44375 | M38: 0.44861111 | N38: 4 | O38: 0.45138889 | P38: =Q38-R38 -> 47 | Q38: =(O38-C38)*1440 -> 60 | R38: =N38+H38 -> 13 | S38: =R38/P38 -> 0.27659574 | T38: =(O38-O37)*1440 -> 30
B39: Morning | C39: 0.43055556 | D39: 0.43472222 | E39: 0.44166667 | F39: 0.44444444 | G39: 0.44583333 | H39: 9 | I39: 0.45208333 | J39: 0.45486111 | K39: 0.45902778 | L39: 0.46458333 | M39: 0.46944444 | N39: 4 | O39: 0.47222222 | P39: =Q39-R39 -> 47 | Q39: =(O39-C39)*1440 -> 60 | R39: =N39+H39 -> 13 | S39: =R39/P39 -> 0.27659574 | T39: =(O39-O38)*1440 -> 30
B40: Morning | C40: 0.45138889 | D40: 0.45555556 | E40: 0.4625 | F40: 0.46527778 | G40: 0.46666667 | H40: 8 | I40: 0.47222222 | J40: 0.475 | K40: 0.47916667 | L40: 0.48472222 | M40: 0.48958333 | N40: 5 | O40: 0.49305556 | P40: =Q40-R40 -> 47 | Q40: =(O40-C40)*1440 -> 60 | R40: =N40+H40 -> 13 | S40: =R40/P40 -> 0.27659574 | T40: =(O40-O39)*1440 -> 30
B41: Midday | C41: 0.47222222 | D41: 0.47708333 | E41: 0.48472222 | F41: 0.4875 | G41: 0.48888889 | H41: 6 | I41: 0.49305556 | J41: 0.49583333 | K41: 0.5 | L41: 0.50625 | M41: 0.51111111 | N41: 4 | O41: 0.51388889 | P41: =Q41-R41 -> 50 | Q41: =(O41-C41)*1440 -> 60 | R41: =N41+H41 -> 10 | S41: =R41/P41 -> 0.2 | T41: =(O41-O40)*1440 -> 30
B42: Midday | C42: 0.49305556 | D42: 0.49791667 | E42: 0.50555556 | F42: 0.50833333 | G42: 0.50972222 | H42: 6 | I42: 0.51388889 | J42: 0.51666667 | K42: 0.52083333 | L42: 0.52708333 | M42: 0.53194444 | N42: 4 | O42: 0.53472222 | P42: =Q42-R42 -> 50 | Q42: =(O42-C42)*1440 -> 60 | R42: =N42+H42 -> 10 | S42: =R42/P42 -> 0.2 | T42: =(O42-O41)*1440 -> 30
B43: Midday | C43: 0.51388889 | D43: 0.51875 | E43: 0.52638889 | F43: 0.52916667 | G43: 0.53055556 | H43: 6 | I43: 0.53472222 | J43: 0.5375 | K43: 0.54166667 | L43: 0.54791667 | M43: 0.55277778 | N43: 4 | O43: 0.55555556 | P43: =Q43-R43 -> 50 | Q43: =(O43-C43)*1440 -> 60 | R43: =N43+H43 -> 10 | S43: =R43/P43 -> 0.2 | T43: =(O43-O42)*1440 -> 30
B44: Midday | C44: 0.53472222 | D44: 0.53958333 | E44: 0.54722222 | F44: 0.55 | G44: 0.55138889 | H44: 6 | I44: 0.55555556 | J44: 0.55833333 | K44: 0.5625 | L44: 0.56875 | M44: 0.57361111 | N44: 4 | O44: 0.57638889 | P44: =Q44-R44 -> 50 | Q44: =(O44-C44)*1440 -> 60 | R44: =N44+H44 -> 10 | S44: =R44/P44 -> 0.2 | T44: =(O44-O43)*1440 -> 30
B45: Midday | C45: 0.55555556 | D45: 0.56041667 | E45: 0.56805556 | F45: 0.57083333 | G45: 0.57222222 | H45: 6 | I45: 0.57638889 | J45: 0.57916667 | K45: 0.58333333 | L45: 0.58958333 | M45: 0.59444444 | N45: 4 | O45: 0.59722222 | P45: =Q45-R45 -> 50 | Q45: =(O45-C45)*1440 -> 60 | R45: =N45+H45 -> 10 | S45: =R45/P45 -> 0.2 | T45: =(O45-O44)*1440 -> 30
B46: Midday | C46: 0.57638889 | D46: 0.58125 | E46: 0.58888889 | F46: 0.59166667 | G46: 0.59305556 | H46: 6 | I46: 0.59722222 | J46: 0.6 | K46: 0.60416667 | L46: 0.61041667 | M46: 0.61527778 | N46: 4 | O46: 0.61805556 | P46: =Q46-R46 -> 50 | Q46: =(O46-C46)*1440 -> 60 | R46: =N46+H46 -> 10 | S46: =R46/P46 -> 0.2 | T46: =(O46-O45)*1440 -> 30
B47: Evening | C47: 0.59722222 | D47: 0.60277778 | E47: 0.60972222 | F47: 0.6125 | G47: 0.61388889 | H47: 6 | I47: 0.61805556 | J47: 0.62083333 | K47: 0.625 | L47: 0.63125 | M47: 0.63611111 | N47: 4 | O47: 0.63888889 | P47: =Q47-R47 -> 50 | Q47: =(O47-C47)*1440 -> 60 | R47: =N47+H47 -> 10 | S47: =R47/P47 -> 0.2 | T47: =(O47-O46)*1440 -> 30
... B52: Evening | C52: 0.70138889 | D52: 0.70694444 | E52: 0.71388889 | F52: 0.71666667 | G52: 0.71805556 | H52: 6 | I52: 0.72222222 | J52: 0.725 | K52: 0.72916667 | L52: 0.73541667 | M52: 0.74027778 | N52: 4 | O52: 0.74305556 | P52: =Q52-R52 -> 50 | Q52: =(O52-C52)*1440 -> 60 | R52: =N52+H52 -> 10 | S52: =R52/P52 -> 0.2 | T52: =(O52-O51)*1440 -> 30
B53: Evening | C53: 0.72222222 | D53: 0.72777778 | E53: 0.73472222 | F53: 0.7375 | G53: 0.73888889 | H53: 6 | I53: 0.74305556 | J53: 0.74583333 | K53: 0.75 | L53: 0.75625 | M53: 0.76111111 | N53: 0 | O53: Block Ends | P53: =Q53-R53 -> 50 | Q53: =(M53-C53)*1440 -> 56 | R53: =N53+H53 -> 6 | S53: =R53/P53 -> 0.12 | T53: =(M53-M52)*1440 -> 30
...

Sheet 100
A1: Weekday | C1: Route | D1: 100 - Red
C2: DEPART | D2: ARRIVE | E2: ARRIVE | G2: DEPART | H2: ARRIVE | J2: DEPART | K2: ARRIVE | M2: DEPART | N2: ARRIVE | P2: DEPART | Q2: ARRIVE | S2: DEPART
B3: Stop Name | C3: Downtown | D3: Bayfield at Highway 400 | E3: Georgian Mall | G3: Georgian Mall | H3: Georgian College | J3: Georgian College | K3: RVH | M3: RVH | N3: Johnson at Blake | P3: Johnson at Blake | Q3: Downtown | S3: Downtown
B4: Stop ID | C4: 1 | D4: 57 | E4: 441 | F4: R | G4: 441 | H4: 330 | I4: R | J4: 330 | K4: 559 | L4: R | M4: 559 | N4: 399 | O4: R | P4: 399 | Q4: 1 | R4: R | S4: 1 | T4: Travel Time | U4: Cycle Time | V4: R | W4: R Ratio | X4: Frequency
B5: Early Morning | C5: 0.29583333 | D5: 0.3 | E5: 0.30416667 | F5: 1 | G5: 0.30486111 | H5: 0.3125 | I5: 0 | J5: 0.3125 | K5: 0.31388889 | L5: 0 | M5: 0.31388889 | N5: 0.31875 | O5: 0 | P5: 0.31875 | Q5: 0.325 | R5: 6 | S5: 0.32916667 | T5: 41 | U5: 48 | V5: 7 | W5: 0.17073171 | Z5: Headway Management
B6: Morning | C6: 0.30902778 | D6: 0.31319444 | E6: 0.31736111 | F6: 1 | G6: 0.31805556 | H6: 0.32638889 | I6: 0 | J6: 0.32638889 | K6: 0.32777778 | L6: 0 | M6: 0.32777778 | N6: 0.33333333 | O6: 0 | P6: 0.33333333 | Q6: 0.33958333 | R6: 7 | S6: 0.34444444 | T6: 43 | U6: 51 | V6: 8 | W6: 0.18604651 | X6: 22 | Z6: Dt Connection
B7: Morning | C7: 0.32916667 | D7: 0.33333333 | E7: 0.3375 | F7: 1 | G7: 0.33819444 | H7: 0.34652778 | I7: 0 | J7: 0.34652778 | K7: 0.34791667 | L7: 0 | M7: 0.34791667 | N7: 0.35347222 | O7: 0 | P7: 0.35347222 | Q7: 0.35972222 | R7: 5 | S7: 0.36319444 | T7: 43 | U7: 49 | V7: 6 | W7: 0.13953488 | X7: 27 | Z7: 400 Connection
B8: Morning | C8: 0.34444444 | D8: 0.34861111 | E8: 0.35277778 | F8: 1 | G8: 0.35347222 | H8: 0.36180556 | I8: 0 | J8: 0.36180556 | K8: 0.36319444 | L8: 0 | M8: 0.36319444 | N8: 0.36875 | O8: 0 | P8: 0.36875 | Q8: 0.375 | R8: 7 | S8: 0.37986111 | T8: 43 | U8: 51 | V8: 8 | W8: 0.18604651 | X8: 24 | Z8: GC Connection
B9: Morning | C9: 0.36319444 | D9: 0.36736111 | E9: 0.37152778 | F9: 1 | G9: 0.37222222 | H9: 0.38055556 | I9: 0 | J9: 0.38055556 | K9: 0.38194444 | L9: 0 | M9: 0.38194444 | N9: 0.3875 | O9: 0 | P9: 0.3875 | Q9: 0.39375 | R9: 5 | S9: 0.39722222 | T9: 43 | U9: 49 | V9: 6 | W9: 0.13953488 | X9: 25 | Z9: GO Train
B10: Morning | C10: 0.37986111 | D10: 0.38402778 | E10: 0.38819444 | F10: 1 | G10: 0.38888889 | H10: 0.39722222 | I10: 0 | J10: 0.39722222 | K10: 0.39861111 | L10: 0 | M10: 0.39861111 | N10: 0.40416667 | O10: 0 | P10: 0.40416667 | Q10: 0.41041667 | R10: 5 | S10: 0.41388889 | T10: 43 | U10: 49 | V10: 6 | W10: 0.13953488 | X10: 24 | Z10: Bayfield Shift Times
B11: Morning | C11: 0.39722222 | D11: 0.40138889 | E11: 0.40555556 | F11: 1 | G11: 0.40625 | H11: 0.41458333 | I11: 0 | J11: 0.41458333 | K11: 0.41597222 | L11: 0 | M11: 0.41597222 | N11: 0.42152778 | O11: 0 | P11: 0.42152778 | Q11: 0.42777778 | R11: 5 | S11: 0.43125 | T11: 43 | U11: 49 | V11: 6 | W11: 0.13953488 | X11: 25 | Z11: Ridership Med (Over 40)
B12: Morning | C12: 0.41388889 | D12: 0.41805556 | E12: 0.42222222 | F12: 1 | G12: 0.42291667 | H12: 0.43125 | I12: 0 | J12: 0.43125 | K12: 0.43263889 | L12: 0 | M12: 0.43263889 | N12: 0.43819444 | O12: 0 | P12: 0.43819444 | Q12: 0.44444444 | R12: 5 | S12: 0.44791667 | T12: 43 | U12: 49 | V12: 6 | W12: 0.13953488 | X12: 24 | Z12: Ridership High (Over 50)
B13: Midday | C13: 0.43125 | D13: 0.43541667 | E13: 0.43958333 | F13: 1 | G13: 0.44027778 | H13: 0.44861111 | I13: 0 | J13: 0.44861111 | K13: 0.45 | L13: 0 | M13: 0.45 | N13: 0.45555556 | O13: 0 | P13: 0.45555556 | Q13: 0.46180556 | R13: 5 | S13: 0.46527778 | T13: 43 | U13: 49 | V13: 6 | W13: 0.13953488 | X13: 25
B14: Midday | C14: 0.44791667 | D14: 0.45208333 | E14: 0.45625 | F14: 1 | G14: 0.45694444 | H14: 0.46527778 | I14: 0 | J14: 0.46527778 | K14: 0.46666667 | L14: 0 | M14: 0.46666667 | N14: 0.47222222 | O14: 0 | P14: 0.47222222 | Q14: 0.47847222 | R14: 5 | S14: 0.48194444 | T14: 43 | U14: 49 | V14: 6 | W14: 0.13953488 | X14: 24
B15: Midday | C15: 0.46527778 | D15: 0.46944444 | E15: 0.47361111 | F15: 1 | G15: 0.47430556 | H15: 0.48263889 | I15: 0 | J15: 0.48263889 | K15: 0.48402778 | L15: 0 | M15: 0.48402778 | N15: 0.48958333 | O15: 0 | P15: 0.48958333 | Q15: 0.49583333 | R15: 5 | S15: 0.49930556 | T15: 43 | U15: 49 | V15: 6 | W15: 0.13953488 | X15: 25
B16: Midday | C16: 0.48194444 | D16: 0.48611111 | E16: 0.49027778 | F16: 1 | G16: 0.49097222 | H16: 0.49930556 | I16: 0 | J16: 0.49930556 | K16: 0.50069444 | L16: 0 | M16: 0.50069444 | N16: 0.50625 | O16: 0 | P16: 0.50625 | Q16: 0.5125 | R16: 5 | S16: 0.51597222 | T16: 43 | U16: 49 | V16: 6 | W16: 0.13953488 | X16: 24
B17: Midday | C17: 0.49930556 | D17: 0.50347222 | E17: 0.50763889 | F17: 1 | G17: 0.50833333 | H17: 0.51666667 | I17: 0 | J17: 0.51666667 | K17: 0.51805556 | L17: 0 | M17: 0.51805556 | N17: 0.52361111 | O17: 0 | P17: 0.52361111 | Q17: 0.52986111 | R17: 5 | S17: 0.53333333 | T17: 43 | U17: 49 | V17: 6 | W17: 0.13953488 | X17: 25
B18: Midday | C18: 0.51597222 | D18: 0.52013889 | E18: 0.52430556 | F18: 1 | G18: 0.525 | H18: 0.53333333 | I18: 0 | J18: 0.53333333 | K18: 0.53472222 | L18: 0 | M18: 0.53472222 | N18: 0.54027778 | O18: 0 | P18: 0.54027778 | Q18: 0.54652778 | R18: 6 | S18: 0.55069444 | T18: 43 | U18: 50 | V18: 7 | W18: 0.1627907 | X18: 25
B19: Peak | C19: 0.53333333 | D19: 0.5375 | E19: 0.54236111 | F19: 1 | G19: 0.54305556 | H19: 0.55138889 | I19: 0 | J19: 0.55138889 | K19: 0.55277778 | L19: 0 | M19: 0.55277778 | N19: 0.55902778 | O19: 0 | P19: 0.55902778 | Q19: 0.56527778 | R19: 5 | S19: 0.56875 | T19: 45 | U19: 51 | V19: 6 | W19: 0.13333333 | X19: 26
B20: Peak | C20: 0.55069444 | D20: 0.55486111 | E20: 0.55972222 | F20: 1 | G20: 0.56041667 | H20: 0.56875 | I20: 0 | J20: 0.56875 | K20: 0.57013889 | L20: 0 | M20: 0.57013889 | N20: 0.57638889 | O20: 0 | P20: 0.57638889 | Q20: 0.58263889 | R20: 5 | S20: 0.58611111 | T20: 45 | U20: 51 | V20: 6 | W20: 0.13333333 | X20: 25
B21: Peak | C21: 0.56875 | D21: 0.57291667 | E21: 0.57777778 | F21: 1 | G21: 0.57847222 | H21: 0.58680556 | I21: 0 | J21: 0.58680556 | K21: 0.58819444 | L21: 0 | M21: 0.58819444 | N21: 0.59444444 | O21: 0 | P21: 0.59444444 | Q21: 0.60069444 | R21: 5 | S21: 0.60416667 | T21: 45 | U21: 51 | V21: 6 | W21: 0.13333333 | X21: 26
B22: Peak | C22: 0.58611111 | D22: 0.59027778 | E22: 0.59513889 | F22: 1 | G22: 0.59583333 | H22: 0.60416667 | I22: 0 | J22: 0.60416667 | K22: 0.60555556 | L22: 0 | M22: 0.60555556 | N22: 0.61180556 | O22: 0 | P22: 0.61180556 | Q22: 0.61805556 | R22: 5 | S22: 0.62152778 | T22: 45 | U22: 51 | V22: 6 | W22: 0.13333333 | X22: 25
B23: Peak | C23: 0.60416667 | D23: 0.60833333 | E23: 0.61319444 | F23: 1 | G23: 0.61388889 | H23: 0.62222222 | I23: 0 | J23: 0.62222222 | K23: 0.62361111 | L23: 0 | M23: 0.62361111 | N23: 0.62986111 | O23: 0 | P23: 0.62986111 | Q23: 0.63611111 | R23: 5 | S23: 0.63958333 | T23: 45 | U23: 51 | V23: 6 | W23: 0.13333333 | X23: 26
B24: Midday | C24: 0.62152778 | D24: 0.62569444 | E24: 0.62986111 | F24: 1 | G24: 0.63055556 | H24: 0.63888889 | I24: 0 | J24: 0.63888889 | K24: 0.64027778 | L24: 0 | M24: 0.64027778 | N24: 0.64583333 | O24: 0 | P24: 0.64583333 | Q24: 0.65208333 | R24: 6 | S24: 0.65625 | T24: 43 | U24: 50 | V24: 7 | W24: 0.1627907 | X24: 24
... B39: Night | C39: 0.87013889 | D39: 0.87430556 | E39: 0.87777778 | F39: 1 | G39: 0.87847222 | H39: 0.88611111 | I39: 0 | J39: 0.88611111 | K39: 0.8875 | L39: 0 | M39: 0.8875 | N39: 0.89305556 | O39: 0 | P39: 0.89305556 | Q39: 0.89861111 | R39: 5 | S39: 0.90208333 | T39: 40 | U39: 46 | V39: 6 | W39: 0.15 | X39: 23
B40: Night | C40: 0.88611111 | D40: 0.89027778 | E40: 0.89375 | F40: 1 | G40: 0.89444444 | H40: 0.90208333 | I40: 0 | J40: 0.90208333 | K40: 0.90347222 | L40: 0 | M40: 0.90347222 | N40: 0.90902778 | O40: 0 | P40: 0.90902778 | Q40: 0.91458333 | T40: 40 | U40: 41 | V40: 1 | W40: 0.025 | X40: 23
B41: Night | C41: 0.90208333 | D41: 0.90625 | E41: 0.90972222 | F41: 1 | G41: 0.91041667 | H41: 0.91805556 | I41: 0 | J41: 0.91805556 | K41: 0.91944444 | L41: 0 | M41: 0.91944444 | N41: 0.925 | O41: 0 | P41: 0.925 | Q41: 0.93055556 | R41: 5 | S41: 0.93402778 | T41: 40 | U41: 46 | V41: 6 | W41: 0.15 | X41: 23
B42: Night | C42: 0.93402778 | D42: 0.93819444 | E42: 0.94166667 | F42: 1 | G42: 0.94236111 | H42: 0.95 | I42: 0 | J42: 0.95 | K42: 0.95138889 | L42: 0 | M42: 0.95138889 | N42: 0.95694444 | O42: 0 | P42: 0.95694444 | Q42: 0.9625 | T42: 40 | U42: 41 | V42: 1 | W42: 0.025 | X42: 46
Q43: Service Hours | T43: 26.1 | U43: =SUM(U5:U42)/60 -> 30.533333 | V43: 3.6333333 | W43: 0.13920817
A44: Saturday
C45: Route | D45: 100 - Red
C46: DEPART | D46: ARRIVE | E46: ARRIVE | G46: DEPART | H46: ARRIVE | J46: DEPART | K46: ARRIVE | M46: DEPART | N46: ARRIVE | P46: DEPART | Q46: ARRIVE | S46: DEPART
B47: Stop Name | C47: Downtown | D47: Bayfield at Highway 400 | E47: Georgian Mall | G47: Georgian Mall | H47: Georgian College | J47: Georgian College | K47: RVH | M47: RVH | N47: Johnson at Blake | P47: Johnson at Blake | Q47: Downtown | S47: Downtown
B48: Stop ID | C48: 1 | D48: 57 | E48: 441 | F48: R | G48: 441 | H48: 330 | I48: R | J48: 330 | K48: 559 | L48: R | M48: 559 | N48: 399 | O48: R | P48: 399 | Q48: 1 | R48: R | S48: 1 | T48: Travel Time | U48: Cycle Time | V48: R | W48: R Ratio | X48: Frequency
B49: Morning | C49: 0.31944444 | D49: 0.32361111 | E49: 0.32777778 | F49: 1 | G49: 0.32847222 | H49: 0.33680556 | I49: 0 | J49: 0.33680556 | K49: 0.33819444 | L49: 0 | M49: 0.33819444 | N49: 0.34375 | O49: 0 | P49: 0.34375 | Q49: 0.35 | R49: 5 | S49: 0.35347222 | T49: 43 | U49: 49 | V49: 6 | W49: 0.13953488
B50: Morning | C50: 0.33611111 | D50: 0.34027778 | E50: 0.34444444 | F50: 1 | G50: 0.34513889 | H50: 0.35347222 | I50: 0 | J50: 0.35347222 | K50: 0.35486111 | L50: 0 | M50: 0.35486111 | N50: 0.36041667 | O50: 0 | P50: 0.36041667 | Q50: 0.36666667 | R50: 5 | S50: 0.37013889 | T50: 43 | U50: 49 | V50: 6 | W50: 0.13953488 | X50: 24
B51: Morning | C51: 0.35347222 | D51: 0.35763889 | E51: 0.36180556 | F51: 1 | G51: 0.3625 | H51: 0.37083333 | I51: 0 | J51: 0.37083333 | K51: 0.37222222 | L51: 0 | M51: 0.37222222 | N51: 0.37777778 | O51: 0 | P51: 0.37777778 | Q51: 0.38402778 | R51: 5 | S51: 0.3875 | T51: 43 | U51: 49 | V51: 6 | W51: 0.13953488 | X51: 25
B52: Morning | C52: 0.37013889 | D52: 0.37430556 | E52: 0.37847222 | F52: 1 | G52: 0.37916667 | H52: 0.3875 | I52: 0 | J52: 0.3875 | K52: 0.38888889 | L52: 0 | M52: 0.38888889 | N52: 0.39444444 | O52: 0 | P52: 0.39444444 | Q52: 0.40069444 | R52: 5 | S52: 0.40416667 | T52: 43 | U52: 49 | V52: 6 | W52: 0.13953488 | X52: 24
B53: Morning | C53: 0.3875 | D53: 0.39166667 | E53: 0.39583333 | F53: 1 | G53: 0.39652778 | H53: 0.40486111 | I53: 0 | J53: 0.40486111 | K53: 0.40625 | L53: 0 | M53: 0.40625 | N53: 0.41180556 | O53: 0 | P53: 0.41180556 | Q53: 0.41805556 | R53: 5 | S53: 0.42152778 | T53: 43 | U53: 49 | V53: 6 | W53: 0.13953488 | X53: 25
B54: Morning | C54: 0.40416667 | D54: 0.40833333 | E54: 0.4125 | F54: 1 | G54: 0.41319444 | H54: 0.42152778 | I54: 0 | J54: 0.42152778 | K54: 0.42291667 | L54: 0 | M54: 0.42291667 | N54: 0.42847222 | O54: 0 | P54: 0.42847222 | Q54: 0.43472222 | R54: 5 | S54: 0.43819444 | T54: 43 | U54: 49 | V54: 6 | W54: 0.13953488 | X54: 24
...

Sheet 101
A1: Weekday | C1: Route | D1: 101 - Blue
C2: DEPART | D2: ARRIVE | F2: DEPART | G2: ARRIVE | I2: DEPART | J2: DEPART | K2: DEPART | L2: DEPART | M2: ARRIVE | O2: DEPART
B3: Stop Name | C3: Downtown | D3: Johnson at Napier | F3: Johnson at Napier | G3: RVH | I3: RVH | J3: Georgian College | K3: Georgian Mall | L3: Bayfield at Highway 400 | M3: Downtown | O3: Downtown
B4: Stop ID | C4: 1 | D4: 400 | E4: R | F4: 400 | G4: 569 | H4: R | I4: 569 | J4: 330 | K4: 441 | L4: 64 | M4: 1 | N4: R | O4: 1 | P4: Travel Time | Q4: Cycle Time | R4: R | S4: R Ratio | T4: Frequency
B5: Morning | C5: 0.29513889 | D5: 0.3 | E5: 1 | F5: 0.30069444 | G5: 0.30555556 | H5: 0 | I5: 0.30555556 | J5: 0.30833333 | K5: 0.31597222 | L5: 0.31944444 | M5: 0.32291667 | N5: 5 | O5: 0.32638889 | P5: 39 | Q5: 45 | R5: 6 | S5: 0.15384615
B6: Morning | C6: 0.31041667 | D6: 0.31527778 | E6: 1 | F6: 0.31597222 | G6: 0.32083333 | H6: 0 | I6: 0.32083333 | J6: 0.32361111 | K6: 0.33125 | L6: 0.33472222 | M6: 0.33819444 | N6: 5 | O6: 0.34166667 | P6: 39 | Q6: 45 | R6: 6 | S6: 0.15384615 | T6: 22
B7: Morning | C7: 0.32638889 | D7: 0.33125 | E7: 1 | F7: 0.33194444 | G7: 0.33680556 | H7: 0 | I7: 0.33680556 | J7: 0.33958333 | K7: 0.34722222 | L7: 0.35069444 | M7: 0.35416667 | N7: 5 | O7: 0.35763889 | P7: 39 | Q7: 45 | R7: 6 | S7: 0.15384615 | T7: 23
B8: Morning | C8: 0.34166667 | D8: 0.34652778 | E8: 1 | F8: 0.34722222 | G8: 0.35208333 | H8: 0 | I8: 0.35208333 | J8: 0.35486111 | K8: 0.3625 | L8: 0.36597222 | M8: 0.36944444 | N8: 5 | O8: 0.37291667 | P8: 39 | Q8: 45 | R8: 6 | S8: 0.15384615 | T8: 22
B9: Morning | C9: 0.35763889 | D9: 0.3625 | E9: 1 | F9: 0.36319444 | G9: 0.36805556 | H9: 0 | I9: 0.36805556 | J9: 0.37083333 | K9: 0.37847222 | L9: 0.38194444 | M9: 0.38541667 | N9: 5 | O9: 0.38888889 | P9: 39 | Q9: 45 | R9: 6 | S9: 0.15384615 | T9: 23
B10: Morning | C10: 0.37291667 | D10: 0.37777778 | E10: 1 | F10: 0.37847222 | G10: 0.38333333 | H10: 0 | I10: 0.38333333 | J10: 0.38611111 | K10: 0.39375 | L10: 0.39722222 | M10: 0.40069444 | N10: 5 | O10: 0.40416667 | P10: 39 | Q10: 45 | R10: 6 | S10: 0.15384615 | T10: 22
B11: Morning | C11: 0.38888889 | D11: 0.39375 | E11: 1 | F11: 0.39444444 | G11: 0.39930556 | H11: 0 | I11: 0.39930556 | J11: 0.40208333 | K11: 0.40972222 | L11: 0.41319444 | M11: 0.41666667 | N11: 5 | O11: 0.42013889 | P11: 39 | Q11: 45 | R11: 6 | S11: 0.15384615 | T11: 23
B12: Morning | C12: 0.40416667 | D12: 0.40902778 | E12: 1 | F12: 0.40972222 | G12: 0.41458333 | H12: 0 | I12: 0.41458333 | J12: 0.41736111 | K12: 0.425 | L12: 0.42847222 | M12: 0.43194444 | N12: 5 | O12: 0.43541667 | P12: 39 | Q12: 45 | R12: 6 | S12: 0.15384615 | T12: 22
B13: Morning | C13: 0.42013889 | D13: 0.425 | E13: 1 | F13: 0.42569444 | G13: 0.43055556 | H13: 0 | I13: 0.43055556 | J13: 0.43333333 | K13: 0.44097222 | L13: 0.44444444 | M13: 0.44791667 | N13: 5 | O13: 0.45138889 | P13: 39 | Q13: 45 | R13: 6 | S13: 0.15384615 | T13: 23
B14: Morning | C14: 0.43541667 | D14: 0.44027778 | E14: 1 | F14: 0.44097222 | G14: 0.44583333 | H14: 0 | I14: 0.44583333 | J14: 0.44861111 | K14: 0.45625 | L14: 0.45972222 | M14: 0.46319444 | N14: 7 | O14: 0.46805556 | P14: 39 | Q14: 47 | R14: 8 | S14: 0.20512821 | T14: 24
B15: Midday | C15: 0.45138889 | D15: 0.45763889 | E15: 1 | F15: 0.45833333 | G15: 0.46388889 | H15: 0 | I15: 0.46388889 | J15: 0.46666667 | K15: 0.475 | L15: 0.47986111 | M15: 0.48333333 | N15: 4 | O15: 0.48611111 | P15: 45 | Q15: 50 | R15: 5 | S15: 0.11111111 | T15: 26
B16: Midday | C16: 0.46805556 | D16: 0.47430556 | E16: 1 | F16: 0.475 | G16: 0.48055556 | H16: 0 | I16: 0.48055556 | J16: 0.48333333 | K16: 0.49166667 | L16: 0.49652778 | M16: 0.5 | N16: 5 | O16: 0.50347222 | P16: 45 | Q16: 51 | R16: 6 | S16: 0.13333333 | T16: 25
B17: Midday | C17: 0.48611111 | D17: 0.49236111 | E17: 1 | F17: 0.49305556 | G17: 0.49861111 | H17: 0 | I17: 0.49861111 | J17: 0.50138889 | K17: 0.50972222 | L17: 0.51458333 | M17: 0.51805556 | N17: 5 | O17: 0.52152778 | P17: 45 | Q17: 51 | R17: 6 | S17: 0.13333333 | T17: 26
... B38: Night | C38: 0.85208333 | D38: 0.85694444 | E38: 1 | F38: 0.85763889 | G38: 0.86319444 | H38: 0 | I38: 0.86319444 | J38: 0.86597222 | K38: 0.87361111 | L38: 0.87708333 | M38: 0.88055556 | N38: 7 | O38: 0.88541667 | P38: 40 | Q38: 48 | R38: 8 | S38: 0.2 | T38: 24
B39: Night | C39: 0.86875 | D39: 0.87361111 | E39: 1 | F39: 0.87430556 | G39: 0.87986111 | H39: 0 | I39: 0.87986111 | J39: 0.88263889 | K39: 0.89027778 | L39: 0.89375 | M39: 0.89722222 | P39: 40 | Q39: 41 | R39: 1 | S39: 0.025 | T39: 24
B40: Night | C40: 0.88541667 | D40: 0.89027778 | E40: 1 | F40: 0.89097222 | G40: 0.89652778 | H40: 0 | I40: 0.89652778 | J40: 0.89930556 | K40: 0.90694444 | L40: 0.91041667 | M40: 0.91388889 | N40: 4 | O40: 0.91666667 | P40: 40 | Q40: 45 | R40: 5 | S40: 0.125 | T40: 24
B41: Night | C41: 0.91666667 | D41: 0.92152778 | E41: 1 | F41: 0.92222222 | G41: 0.92777778 | H41: 0 | I41: 0.92777778 | J41: 0.93055556 | K41: 0.93819444 | L41: 0.94166667 | M41: 0.94513889 | O41: 0.94513889 | P41: 40 | Q41: 41 | R41: 1 | S41: 0.025 | T41: 45
M42: Service Hours | P42: 26 | Q42: 29.683333 | R42: 3.6833333 | S42: 0.14166667
A43: Saturday
C44: Route | D44: 101 - Blue
C45: DEPART | D45: ARRIVE | F45: DEPART | G45: ARRIVE | I45: DEPART | J45: DEPART | K45: DEPART | L45: DEPART | M45: ARRIVE | O45: DEPART
B46: Stop Name | C46: Downtown | D46: Johnson at Napier | F46: Johnson at Napier | G46: RVH | I46: RVH | J46: Georgian College | K46: Georgian Mall | L46: Bayfield at Highway 400 | M46: Downtown | O46: Downtown
B47: Stop ID | C47: 1 | D47: 400 | E47: R | F47: 400 | G47: 569 | H47: R | I47: 569 | J47: 330 | K47: 441 | L47: 64 | M47: 1 | N47: R | O47: 1 | P47: Travel Time | Q47: Cycle Time | R47: R | S47: R Ratio | T47: Frequency
B48: Morning | C48: 0.30208333 | D48: 0.30694444 | E48: 1 | F48: 0.30763889 | G48: 0.3125 | H48: 0 | I48: 0.3125 | J48: 0.31527778 | K48: 0.32291667 | L48: 0.32638889 | M48: 0.32986111 | N48: 5 | O48: 0.33333333 | P48: 39 | Q48: 45 | R48: 6 | S48: 0.15384615
B49: Morning | C49: 0.33333333 | D49: 0.33819444 | E49: 1 | F49: 0.33888889 | G49: 0.34375 | H49: 0 | I49: 0.34375 | J49: 0.34652778 | K49: 0.35416667 | L49: 0.35763889 | M49: 0.36111111 | N49: 5 | O49: 0.36458333 | P49: 39 | Q49: 45 | R49: 6 | S49: 0.15384615 | T49: 45
B50: Morning | C50: 0.34861111 | D50: 0.35347222 | E50: 1 | F50: 0.35416667 | G50: 0.35902778 | H50: 0 | I50: 0.35902778 | J50: 0.36180556 | K50: 0.36944444 | L50: 0.37291667 | M50: 0.37638889 | N50: 5 | O50: 0.37986111 | P50: 39 | Q50: 45 | R50: 6 | S50: 0.15384615 | T50: 22
B51: Morning | C51: 0.36458333 | D51: 0.36944444 | E51: 1 | F51: 0.37013889 | G51: 0.375 | H51: 0 | I51: 0.375 | J51: 0.37777778 | K51: 0.38541667 | L51: 0.38888889 | M51: 0.39236111 | N51: 5 | O51: 0.39583333 | P51: 39 | Q51: 45 | R51: 6 | S51: 0.15384615 | T51: 23
B52: Morning | C52: 0.37986111 | D52: 0.38472222 | E52: 1 | F52: 0.38541667 | G52: 0.39027778 | H52: 0 | I52: 0.39027778 | J52: 0.39305556 | K52: 0.40069444 | L52: 0.40416667 | M52: 0.40763889 | N52: 5 | O52: 0.41111111 | P52: 39 | Q52: 45 | R52: 6 | S52: 0.15384615 | T52: 22
B53: Morning | C53: 0.39583333 | D53: 0.40069444 | E53: 1 | F53: 0.40138889 | G53: 0.40625 | H53: 0 | I53: 0.40625 | J53: 0.40902778 | K53: 0.41666667 | L53: 0.42013889 | M53: 0.42361111 | N53: 5 | O53: 0.42708333 | P53: 39 | Q53: 45 | R53: 6 | S53: 0.15384615 | T53: 23
B54: Morning | C54: 0.41111111 | D54: 0.41597222 | E54: 1 | F54: 0.41666667 | G54: 0.42152778 | H54: 0 | I54: 0.42152778 | J54: 0.42430556 | K54: 0.43194444 | L54: 0.43541667 | M54: 0.43888889 | N54: 5 | O54: 0.44236111 | P54: 39 | Q54: 45 | R54: 6 | S54: 0.15384615 | T54: 22
B55: Morning | C55: 0.42708333 | D55: 0.43194444 | E55: 1 | F55: 0.43263889 | G55: 0.4375 | H55: 0 | I55: 0.4375 | J55: 0.44027778 | K55: 0.44791667 | L55: 0.45138889 | M55: 0.45486111 | N55: 5 | O55: 0.45833333 | P55: 39 | Q55: 45 | R55: 6 | S55: 0.15384615 | T55: 23
B56: Morning | C56: 0.44236111 | D56: 0.44722222 | E56: 1 | F56: 0.44791667 | G56: 0.45277778 | H56: 0 | I56: 0.45277778 | J56: 0.45555556 | K56: 0.46319444 | L56: 0.46666667 | M56: 0.47013889 | N56: 5 | O56: 0.47361111 | P56: 39 | Q56: 45 | R56: 6 | S56: 0.15384615 | T56: 22
B57: Morning | C57: 0.45833333 | D57: 0.46319444 | E57: 1 | F57: 0.46388889 | G57: 0.46875 | H57: 0 | I57: 0.46875 | J57: 0.47152778 | K57: 0.47916667 | L57: 0.48263889 | M57: 0.48611111 | N57: 5 | O57: 0.48958333 | P57: 39 | Q57: 45 | R57: 6 | S57: 0.15384615 | T57: 23
B58: Morning | C58: 0.47361111 | D58: 0.47847222 | E58: 1 | F58: 0.47916667 | G58: 0.48402778 | H58: 0 | I58: 0.48402778 | J58: 0.48680556 | K58: 0.49444444 | L58: 0.49791667 | M58: 0.50138889 | N58: 5 | O58: 0.50486111 | P58: 39 | Q58: 45 | R58: 6 | S58: 0.15384615 | T58: 22
B59: Morning | C59: 0.48958333 | D59: 0.49444444 | E59: 1 | F59: 0.49513889 | G59: 0.5 | H59: 0 | I59: 0.5 | J59: 0.50277778 | K59: 0.51041667 | L59: 0.51388889 | M59: 0.51736111 | N59: 5 | O59: 0.52083333 | P59: 39 | Q59: 45 | R59: 6 | S59: 0.15384615 | T59: 23
B60: Morning | C60: 0.50486111 | D60: 0.50972222 | E60: 1 | F60: 0.51041667 | G60: 0.51527778 | H60: 0 | I60: 0.51527778 | J60: 0.51805556 | K60: 0.52569444 | L60: 0.52916667 | M60: 0.53263889 | N60: 5 | O60: 0.53611111 | P60: 39 | Q60: 45 | R60: 6 | S60: 0.15384615 | T60: 22
...

Sheet 2
A1: Weekday | C1: 2A | L1: 2B
C2: DEPART | E2: ARRIVE | G2: DEPART | J2: ARRIVE | L2: DEPART | O2: ARRIVE | Q2: DEPART | S2: ARRIVE | U2: DEPART
B3: Stop Name | C3: Park Place | D3: Veteran's at Essa | E3: Cuthbert Street | G3: =E3 -> Cuthbert Street | H3: Sproule at Kraus | I3: Dunlop at Ferndale | J3: Downtown | L3: Downtown | M3: Ferndale Drive | N3: Sproule at Kraus | O3: Ferndale Woods Public School | Q3: =O3 -> Ferndale Woods Public School | R3: Veteran's at Essa | S3: Park Place | U3: Park Place
B4: Stop ID | C4: 777 | D4: 662 | E4: 829 | F4: R | G4: =E4 -> 829 | H4: 627 | I4: 271 | J4: 1 | K4: R | L4: 1 | M4: 893 | N4: 626 | O4: 841 | P4: R | Q4: =O4 -> 841 | R4: 847 | S4: 777 | T4: R | U4: 777 | V4: Travel Time | W4: Cycle Time | X4: R | Y4: R Ratio | Z4: Frequency | AD4: Headway Management
B5: Early Morning | H5: 0.22638889 | I5: 0.23055556 | J5: 0.23611111 | K5: 8 | L5: 0.24166667 | M5: 0.24652778 | N5: 0.25138889 | O5: =ARRAY_CONSTRAIN(ARRAYFORMULA(Q5+TIME(,OFFSET([2]Segment!$C$83,,$B5,),)), 1, 1) -> #ERROR! | P5: 2 | Q5: =O5+TIME(,P5,) -> #ERROR! | R5: 0.26111111 | S5: 0.26805556 | T5: 9 | U5: 0.27430556 | V5: =W5-X5 -> 50 | W5: =(U5-H5)*1440 -> 69 | X5: =K5+F5+T5+P5 -> 19 | Y5: =X5/V5 -> 0.38 | AD5: DT Connection
B6: Early Morning | H6: 0.24722222 | I6: 0.25138889 | J6: 0.25694444 | K6: 8 | L6: 0.2625 | M6: 0.26736111 | N6: 0.27222222 | O6: =ARRAY_CONSTRAIN(ARRAYFORMULA(Q6+TIME(,OFFSET([2]Segment!$C$83,,$B6,),)), 1, 1) -> #ERROR! | P6: 2 | Q6: =O6+TIME(,P6,) -> #ERROR! | R6: 0.28194444 | S6: 0.28888889 | T6: 9 | U6: 0.29513889 | V6: =W6-X6 -> 50 | W6: =(U6-H6)*1440 -> 69 | X6: =K6+F6+T6+P6 -> 19 | Y6: =X6/V6 -> 0.38 | Z6: =(U6-U5)*1440 -> 30 | AD6: 400 Connection
B7: Morning | C7: 0.25347222 | D7: 0.25972222 | E7: =ARRAY_CONSTRAIN(ARRAYFORMULA(G7+TIME(,OFFSET([2]Segment!$C$77,,$B7,),)), 1, 1) -> #ERROR! | F7: 2 | G7: =E7+TIME(,F7,) -> #ERROR! | H7: 0.26805556 | I7: 0.27222222 | J7: 0.27777778 | K7: 8 | L7: 0.28333333 | M7: 0.28819444 | N7: 0.29305556 | O7: =ARRAY_CONSTRAIN(ARRAYFORMULA(Q7+TIME(,OFFSET([2]Segment!$C$83,,$B7,),)), 1, 1) -> #ERROR! | P7: 2 | Q7: =O7+TIME(,P7,) -> #ERROR! | R7: 0.30277778 | S7: 0.30972222 | T7: 9 | U7: 0.31597222 | V7: =W7-X7 -> 69 | W7: =(U7-C7)*1440 -> 90 | X7: =K7+F7+T7+P7 -> 21 | Y7: =X7/V7 -> 0.30434783 | Z7: =(U7-U6)*1440 -> 30 | AD7: GC Connection
B8: Morning | C8: 0.27430556 | D8: 0.28055556 | E8: =ARRAY_CONSTRAIN(ARRAYFORMULA(G8+TIME(,OFFSET([2]Segment!$C$77,,$B8,),)), 1, 1) -> #ERROR! | F8: 2 | G8: =E8+TIME(,F8,) -> #ERROR! | H8: 0.28888889 | I8: 0.29305556 | J8: 0.29861111 | K8: 8 | L8: 0.30416667 | M8: 0.30902778 | N8: 0.31388889 | O8: =ARRAY_CONSTRAIN(ARRAYFORMULA(Q8+TIME(,OFFSET([2]Segment!$C$83,,$B8,),)), 1, 1) -> #ERROR! | P8: 2 | Q8: =O8+TIME(,P8,) -> #ERROR! | R8: 0.32361111 | S8: 0.33055556 | T8: 9 | U8: 0.33680556 | V8: =W8-X8 -> 69 | W8: =(U8-C8)*1440 -> 90 | X8: =K8+F8+T8+P8 -> 21 | Y8: =X8/V8 -> 0.30434783 | Z8: =(U8-U7)*1440 -> 30 | AD8: GO Train
B9: Morning | C9: 0.29513889 | D9: 0.30138889 | E9: =ARRAY_CONSTRAIN(ARRAYFORMULA(G9+TIME(,OFFSET([2]Segment!$C$77,,$B9,),)), 1, 1) -> #ERROR! | F9: 2 | G9: =E9+TIME(,F9,) -> #ERROR! | H9: 0.30972222 | I9: 0.31388889 | J9: 0.31944444 | K9: 8 | L9: 0.325 | M9: 0.32986111 | N9: 0.33472222 | O9: =ARRAY_CONSTRAIN(ARRAYFORMULA(Q9+TIME(,OFFSET([2]Segment!$C$83,,$B9,),)), 1, 1) -> #ERROR! | P9: 2 | Q9: =O9+TIME(,P9,) -> #ERROR! | R9: 0.34444444 | S9: 0.35138889 | T9: 9 | U9: 0.35763889 | V9: =W9-X9 -> 69 | W9: =(U9-C9)*1440 -> 90 | X9: =K9+F9+T9+P9 -> 21 | Y9: =X9/V9 -> 0.30434783 | Z9: =(U9-U8)*1440 -> 30 | AD9: High School
B10: Morning | C10: 0.31597222 | D10: 0.32222222 | E10: =ARRAY_CONSTRAIN(ARRAYFORMULA(G10+TIME(,OFFSET([2]Segment!$C$77,,$B10,),)), 1, 1) -> #ERROR! | F10: 2 | G10: =E10+TIME(,F10,) -> #ERROR! | H10: 0.33055556 | I10: 0.33472222 | J10: 0.34027778 | K10: 8 | L10: 0.34583333 | M10: 0.35069444 | N10: 0.35555556 | O10: =ARRAY_CONSTRAIN(ARRAYFORMULA(Q10+TIME(,OFFSET([2]Segment!$C$83,,$B10,),)), 1, 1) -> #ERROR! | P10: 2 | Q10: =O10+TIME(,P10,) -> #ERROR! | R10: 0.36527778 | S10: 0.37222222 | T10: 9 | U10: 0.37847222 | V10: =W10-X10 -> 69 | W10: =(U10-C10)*1440 -> 90 | X10: =K10+F10+T10+P10 -> 21 | Y10: =X10/V10 -> 0.30434783 | Z10: =(U10-U9)*1440 -> 30
B11: Morning | C11: 0.33680556 | D11: 0.34305556 | E11: =ARRAY_CONSTRAIN(ARRAYFORMULA(G11+TIME(,OFFSET([2]Segment!$C$77,,$B11,),)), 1, 1) -> #ERROR! | F11: 2 | G11: =E11+TIME(,F11,) -> #ERROR! | H11: 0.35138889 | I11: 0.35555556 | J11: 0.36111111 | K11: 8 | L11: 0.36666667 | M11: 0.37152778 | N11: 0.37638889 | O11: =ARRAY_CONSTRAIN(ARRAYFORMULA(Q11+TIME(,OFFSET([2]Segment!$C$83,,$B11,),)), 1, 1) -> #ERROR! | P11: 2 | Q11: =O11+TIME(,P11,) -> #ERROR! | R11: 0.38611111 | S11: 0.39305556 | T11: 9 | U11: 0.39930556 | V11: =W11-X11 -> 69 | W11: =(U11-C11)*1440 -> 90 | X11: =K11+F11+T11+P11 -> 21 | Y11: =X11/V11 -> 0.30434783 | Z11: =(U11-U10)*1440 -> 30
B12: Morning | C12: 0.35763889 | D12: 0.36388889 | E12: =ARRAY_CONSTRAIN(ARRAYFORMULA(G12+TIME(,OFFSET([2]Segment!$C$77,,$B12,),)), 1, 1) -> #ERROR! | F12: 2 | G12: =E12+TIME(,F12,) -> #ERROR! | H12: 0.37222222 | I12: 0.37638889 | J12: 0.38194444 | K12: 8 | L12: 0.3875 | M12: 0.39236111 | N12: 0.39722222 | O12: =ARRAY_CONSTRAIN(ARRAYFORMULA(Q12+TIME(,OFFSET([2]Segment!$C$83,,$B12,),)), 1, 1) -> #ERROR! | P12: 2 | Q12: =O12+TIME(,P12,) -> #ERROR! | R12: 0.40694444 | S12: 0.41388889 | T12: 9 | U12: 0.42013889 | V12: =W12-X12 -> 69 | W12: =(U12-C12)*1440 -> 90 | X12: =K12+F12+T12+P12 -> 21 | Y12: =X12/V12 -> 0.30434783 | Z12: =(U12-U11)*1440 -> 30
B13: Morning | C13: 0.37847222 | D13: 0.38472222 | E13: =ARRAY_CONSTRAIN(ARRAYFORMULA(G13+TIME(,OFFSET([2]Segment!$C$77,,$B13,),)), 1, 1) -> #ERROR! | F13: 2 | G13: =E13+TIME(,F13,) -> #ERROR! | H13: 0.39305556 | I13: 0.39722222 | J13: 0.40277778 | K13: 8 | L13: 0.40833333 | M13: 0.41319444 | N13: 0.41805556 | O13: =ARRAY_CONSTRAIN(ARRAYFORMULA(Q13+TIME(,OFFSET([2]Segment!$C$83,,$B13,),)), 1, 1) -> #ERROR! | P13: 2 | Q13: =O13+TIME(,P13,) -> #ERROR! | R13: 0.42777778 | S13: 0.43472222 | T13: 9 | U13: 0.44097222 | V13: =W13-X13 -> 69 | W13: =(U13-C13)*1440 -> 90 | X13: =K13+F13+T13+P13 -> 21 | Y13: =X13/V13 -> 0.30434783 | Z13: =(U13-U12)*1440 -> 30
B14: Morning | C14: 0.39930556 | D14: 0.40555556 | E14: =ARRAY_CONSTRAIN(ARRAYFORMULA(G14+TIME(,OFFSET([2]Segment!$C$77,,$B14,),)), 1, 1) -> #ERROR! | F14: 2 | G14: =E14+TIME(,F14,) -> #ERROR! | H14: 0.41388889 | I14: 0.41805556 | J14: 0.42361111 | K14: 8 | L14: 0.42916667 | M14: 0.43402778 | N14: 0.43888889 | O14: =ARRAY_CONSTRAIN(ARRAYFORMULA(Q14+TIME(,OFFSET([2]Segment!$C$83,,$B14,),)), 1, 1) -> #ERROR! | P14: 2 | Q14: =O14+TIME(,P14,) -> #ERROR! | R14: 0.44861111 | S14: 0.45555556 | T14: 9 | U14: 0.46180556 | V14: =W14-X14 -> 69 | W14: =(U14-C14)*1440 -> 90 | X14: =K14+F14+T14+P14 -> 21 | Y14: =X14/V14 -> 0.30434783 | Z14: =(U14-U13)*1440 -> 30
B15: Morning | C15: 0.42013889 | D15: 0.42638889 | E15: =ARRAY_CONSTRAIN(ARRAYFORMULA(G15+TIME(,OFFSET([2]Segment!$C$77,,$B15,),)), 1, 1) -> #ERROR! | F15: 2 | G15: =E15+TIME(,F15,) -> #ERROR! | H15: 0.43472222 | I15: 0.43888889 | J15: 0.44444444 | K15: 8 | L15: 0.45 | M15: 0.45486111 | N15: 0.45972222 | O15: =ARRAY_CONSTRAIN(ARRAYFORMULA(Q15+TIME(,OFFSET([2]Segment!$C$83,,$B15,),)), 1, 1) -> #ERROR! | P15: 2 | Q15: =O15+TIME(,P15,) -> #ERROR! | R15: 0.46944444 | S15: 0.47638889 | T15: 9 | U15: 0.48263889 | V15: =W15-X15 -> 69 | W15: =(U15-C15)*1440 -> 90 | X15: =K15+F15+T15+P15 -> 21 | Y15: =X15/V15 -> 0.30434783 | Z15: =(U15-U14)*1440 -> 30
B16: Midday | C16: 0.44097222 | D16: 0.44791667 | E16: =ARRAY_CONSTRAIN(ARRAYFORMULA(G16+TIME(,OFFSET([2]Segment!$C$77,,$B16,),)), 1, 1) -> #ERROR! | F16: 2 | G16: =E16+TIME(,F16,) -> #ERROR! | H16: 0.45625 | I16: 0.46041667 | J16: 0.46597222 | K16: 7 | L16: 0.47083333 | M16: 0.47569444 | N16: 0.48055556 | O16: =ARRAY_CONSTRAIN(ARRAYFORMULA(Q16+TIME(,OFFSET([2]Segment!$C$83,,$B16,),)), 1, 1) -> #ERROR! | P16: 2 | Q16: =O16+TIME(,P16,) -> #ERROR! | R16: 0.49097222 | S16: 0.49861111 | T16: 7 | U16: 0.50347222 | V16: =W16-X16 -> 72 | W16: =(U16-C16)*1440 -> 90 | X16: =K16+F16+T16+P16 -> 18 | Y16: =X16/V16 -> 0.25 | Z16: =(U16-U15)*1440 -> 30
B17: Midday | C17: 0.46180556 | D17: 0.46875 | E17: =ARRAY_CONSTRAIN(ARRAYFORMULA(G17+TIME(,OFFSET([2]Segment!$C$77,,$B17,),)), 1, 1) -> #ERROR! | F17: 2 | G17: =E17+TIME(,F17,) -> #ERROR! | H17: 0.47708333 | I17: 0.48125 | J17: 0.48680556 | K17: 7 | L17: 0.49166667 | M17: 0.49652778 | N17: 0.50138889 | O17: =ARRAY_CONSTRAIN(ARRAYFORMULA(Q17+TIME(,OFFSET([2]Segment!$C$83,,$B17,),)), 1, 1) -> #ERROR! | P17: 2 | Q17: =O17+TIME(,P17,) -> #ERROR! | R17: 0.51180556 | S17: 0.51944444 | T17: 7 | U17: 0.52430556 | V17: =W17-X17 -> 72 | W17: =(U17-C17)*1440 -> 90 | X17: =K17+F17+T17+P17 -> 18 | Y17: =X17/V17 -> 0.25 | Z17: =(U17-U16)*1440 -> 30
B18: Midday | C18: 0.48263889 | D18: 0.48958333 | E18: =ARRAY_CONSTRAIN(ARRAYFORMULA(G18+TIME(,OFFSET([2]Segment!$C$77,,$B18,),)), 1, 1) -> #ERROR! | F18: 2 | G18: =E18+TIME(,F18,) -> #ERROR! | H18: 0.49791667 | I18: 0.50208333 | J18: 0.50763889 | K18: 7 | L18: 0.5125 | M18: 0.51736111 | N18: 0.52222222 | O18: =ARRAY_CONSTRAIN(ARRAYFORMULA(Q18+TIME(,OFFSET([2]Segment!$C$83,,$B18,),)), 1, 1) -> #ERROR! | P18: 2 | Q18: =O18+TIME(,P18,) -> #ERROR! | R18: 0.53263889 | S18: 0.54027778 | T18: 7 | U18: 0.54513889 | V18: =W18-X18 -> 72 | W18: =(U18-C18)*1440 -> 90 | X18: =K18+F18+T18+P18 -> 18 | Y18: =X18/V18 -> 0.25 | Z18: =(U18-U17)*1440 -> 30
B19: Midday | C19: 0.50347222 | D19: 0.51041667 | E19: =ARRAY_CONSTRAIN(ARRAYFORMULA(G19+TIME(,OFFSET([2]Segment!$C$77,,$B19,),)), 1, 1) -> #ERROR! | F19: 2 | G19: =E19+TIME(,F19,) -> #ERROR! | H19: 0.51875 | I19: 0.52291667 | J19: 0.52847222 | K19: 7 | L19: 0.53333333 | M19: 0.53819444 | N19: 0.54305556 | O19: =ARRAY_CONSTRAIN(ARRAYFORMULA(Q19+TIME(,OFFSET([2]Segment!$C$83,,$B19,),)), 1, 1) -> #ERROR! | P19: 2 | Q19: =O19+TIME(,P19,) -> #ERROR! | R19: 0.55347222 | S19: 0.56111111 | T19: 7 | U19: 0.56597222 | V19: =W19-X19 -> 72 | W19: =(U19-C19)*1440 -> 90 | X19: =K19+F19+T19+P19 -> 18 | Y19: =X19/V19 -> 0.25 | Z19: =(U19-U18)*1440 -> 30
B20: Midday | C20: 0.52430556 | D20: 0.53125 | E20: =ARRAY_CONSTRAIN(ARRAYFORMULA(G20+TIME(,OFFSET([2]Segment!$C$77,,$B20,),)), 1, 1) -> #ERROR! | F20: 2 | G20: =E20+TIME(,F20,) -> #ERROR! | H20: 0.53958333 | I20: 0.54375 | J20: 0.54930556 | K20: 7 | L20: 0.55416667 | M20: 0.55902778 | N20: 0.56388889 | O20: =ARRAY_CONSTRAIN(ARRAYFORMULA(Q20+TIME(,OFFSET([2]Segment!$C$83,,$B20,),)), 1, 1) -> #ERROR! | P20: 2 | Q20: =O20+TIME(,P20,) -> #ERROR! | R20: 0.57430556 | S20: 0.58194444 | T20: 7 | U20: 0.58680556 | V20: =W20-X20 -> 72 | W20: =(U20-C20)*1440 -> 90 | X20: =K20+F20+T20+P20 -> 18 | Y20: =X20/V20 -> 0.25 | Z20: =(U20-U19)*1440 -> 30
B21: Midday | C21: 0.54513889 | D21: 0.55208333 | E21: =ARRAY_CONSTRAIN(ARRAYFORMULA(G21+TIME(,OFFSET([2]Segment!$C$77,,$B21,),)), 1, 1) -> #ERROR! | F21: 2 | G21: =E21+TIME(,F21,) -> #ERROR! | H21: 0.56041667 | I21: 0.56458333 | J21: 0.57013889 | K21: 7 | L21: 0.575 | M21: 0.57986111 | N21: 0.58472222 | O21: =ARRAY_CONSTRAIN(ARRAYFORMULA(Q21+TIME(,OFFSET([2]Segment!$C$83,,$B21,),)), 1, 1) -> #ERROR! | P21: 2 | Q21: =O21+TIME(,P21,) -> #ERROR! | R21: 0.59513889 | S21: 0.60277778 | T21: 7 | U21: 0.60763889 | V21: =W21-X21 -> 72 | W21: =(U21-C21)*1440 -> 90 | X21: =K21+F21+T21+P21 -> 18 | Y21: =X21/V21 -> 0.25 | Z21: =(U21-U20)*1440 -> 30
... B30: Evening | C30: 0.73263889 | D30: 0.74027778 | E30: =ARRAY_CONSTRAIN(ARRAYFORMULA(G30+TIME(,OFFSET([2]Segment!$C$77,,$B30,),)), 1, 1) -> #ERROR! | F30: 2 | G30: =E30+TIME(,F30,) -> #ERROR! | H30: 0.74861111 | I30: 0.75277778 | J30: 0.75833333 | K30: 6 | L30: 0.7625 | M30: 0.76666667 | N30: 0.77083333 | O30: =ARRAY_CONSTRAIN(ARRAYFORMULA(Q30+TIME(,OFFSET([2]Segment!$C$83,,$B30,),)), 1, 1) -> #ERROR! | P30: 2 | Q30: =O30+TIME(,P30,) -> #ERROR! | R30: 0.77986111 | S30: 0.7875 | T30: 11 | U30: 0.79513889 | V30: =W30-X30 -> 69 | W30: =(U30-C30)*1440 -> 90 | X30: =K30+F30+T30+P30 -> 21 | Y30: =X30/V30 -> 0.30434783 | Z30: =(U30-U29)*1440 -> 30
B31: Evening | C31: 0.75347222 | D31: 0.76111111 | E31: =ARRAY_CONSTRAIN(ARRAYFORMULA(G31+TIME(,OFFSET([2]Segment!$C$77,,$B31,),)), 1, 1) -> #ERROR! | F31: 2 | G31: =E31+TIME(,F31,) -> #ERROR! | H31: 0.76944444 | I31: 0.77361111 | J31: 0.77916667 | K31: 6 | L31: 0.78333333 | M31: 0.7875 | N31: 0.79166667 | O31: =ARRAY_CONSTRAIN(ARRAYFORMULA(Q31+TIME(,OFFSET([2]Segment!$C$83,,$B31,),)), 1, 1) -> #ERROR! | P31: 2 | Q31: =O31+TIME(,P31,) -> #ERROR! | R31: 0.80069444 | S31: 0.80833333 | T31: 0 | U31: Block Ends | V31: =W31-X31 -> 69 | W31: =(S31-C31)*1440 -> 79 | X31: =K31+F31+T31+P31 -> 10 | Y31: =X31/V31 -> 0.14492754 | Z31: =(S31-S30)*1440 -> 30
B32: Evening | C32: 0.77430556 | D32: 0.78194444 | E32: =ARRAY_CONSTRAIN(ARRAYFORMULA(G32+TIME(,OFFSET([2]Segment!$C$77,,$B32,),)), 1, 1) -> #ERROR! | F32: 2 | G32: =E32+TIME(,F32,) -> #ERROR! | H32: 0.79027778 | I32: 0.79444444 | J32: 0.8 | K32: 6 | L32: 0.80416667 | M32: 0.80833333 | N32: 0.8125 | O32: =ARRAY_CONSTRAIN(ARRAYFORMULA(Q32+TIME(,OFFSET([2]Segment!$C$83,,$B32,),)), 1, 1) -> #ERROR! | P32: 2 | Q32: =O32+TIME(,P32,) -> #ERROR! | R32: 0.82152778 | S32: 0.82916667 | T32: 11 | U32: 0.83680556 | V32: =W32-X32 -> 69 | W32: =(U32-C32)*1440 -> 90 | X32: =K32+F32+T32+P32 -> 21 | Y32: =X32/V32 -> 0.30434783 | Z32: =(S32-S31)*1440 -> 30
B33: Evening | C33: 0.79513889 | D33: 0.80277778 | E33: =ARRAY_CONSTRAIN(ARRAYFORMULA(G33+TIME(,OFFSET([2]Segment!$C$77,,$B33,),)), 1, 1) -> #ERROR! | F33: 2 | G33: =E33+TIME(,F33,) -> #ERROR! | H33: 0.81111111 | I33: 0.81527778 | J33: 0.82083333 | K33: 6 | L33: 0.825 | M33: 0.82916667 | N33: 0.83333333 | O33: =ARRAY_CONSTRAIN(ARRAYFORMULA(Q33+TIME(,OFFSET([2]Segment!$C$83,,$B33,),)), 1, 1) -> #ERROR! | P33: 2 | Q33: =O33+TIME(,P33,) -> #ERROR! | R33: 0.84236111 | S33: 0.85 | T33: 11 | U33: 0.85763889 | V33: =W33-X33 -> 69 | W33: =(U33-C33)*1440 -> 90 | X33: =K33+F33+T33+P33 -> 21 | Y33: =X33/V33 -> 0.30434783 | Z33: =(U33-U32)*1440 -> 30
B34: Evening | C34: 0.83680556 | D34: 0.84444444 | E34: =ARRAY_CONSTRAIN(ARRAYFORMULA(G34+TIME(,OFFSET([2]Segment!$C$77,,$B34,),)), 1, 1) -> #ERROR! | F34: 2 | G34: =E34+TIME(,F34,) -> #ERROR! | H34: 0.85277778 | I34: 0.85694444 | J34: 0.8625 | K34: 6 | L34: 0.86666667 | M34: 0.87083333 | N34: 0.875 | O34: =ARRAY_CONSTRAIN(ARRAYFORMULA(Q34+TIME(,OFFSET([2]Segment!$C$83,,$B34,),)), 1, 1) -> #ERROR! | P34: 2 | Q34: =O34+TIME(,P34,) -> #ERROR! | R34: 0.88402778 | S34: 0.89166667 | T34: 11 | U34: 0.89930556 | V34: =W34-X34 -> 69 | W34: =(U34-C34)*1440 -> 90 | X34: =K34+F34+T34+P34 -> 21 | Y34: =X34/V34 -> 0.30434783 | Z34: =(U34-U33)*1440 -> 60
B35: Night | C35: 0.85763889 | D35: 0.86388889 | E35: =ARRAY_CONSTRAIN(ARRAYFORMULA(G35+TIME(,OFFSET([2]Segment!$C$77,,$B35,),)), 1, 1) -> #ERROR! | F35: 2 | G35: =E35+TIME(,F35,) -> #ERROR! | H35: 0.87222222 | I35: 0.87638889 | J35: 0.88194444 | K35: 8 | L35: 0.8875 | M35: 0.89166667 | N35: 0.89513889 | O35: =ARRAY_CONSTRAIN(ARRAYFORMULA(Q35+TIME(,OFFSET([2]Segment!$C$83,,$B35,),)), 1, 1) -> #ERROR! | P35: 2 | Q35: =O35+TIME(,P35,) -> #ERROR! | R35: 0.90555556 | S35: 0.91180556 | T35: 12 | U35: 0.92013889 | V35: =W35-X35 -> 66 | W35: =(U35-C35)*1440 -> 90 | X35: =K35+F35+T35+P35 -> 24 | Y35: =X35/V35 -> 0.36363636 | Z35: =(U35-U34)*1440 -> 30
B36: Night | C36: 0.89930556 | D36: 0.90555556 | E36: =ARRAY_CONSTRAIN(ARRAYFORMULA(G36+TIME(,OFFSET([2]Segment!$C$77,,$B36,),)), 1, 1) -> #ERROR! | F36: 2 | G36: =E36+TIME(,F36,) -> #ERROR! | H36: 0.91388889 | I36: 0.91805556 | J36: 0.92361111 | K36: 8 | L36: 0.92916667 | M36: 0.93333333 | N36: 0.93680556 | O36: =ARRAY_CONSTRAIN(ARRAYFORMULA(Q36+TIME(,OFFSET([2]Segment!$C$83,,$B36,),)), 1, 1) -> #ERROR! | P36: 2 | Q36: =O36+TIME(,P36,) -> #ERROR! | R36: 0.94722222 | S36: 0.95347222 | T36: 12 | U36: 0.96180556 | V36: =W36-X36 -> 66 | W36: =(U36-C36)*1440 -> 90 | X36: =K36+F36+T36+P36 -> 24 | Y36: =X36/V36 -> 0.36363636 | Z36: =(U36-U35)*1440 -> 60
B37: Night | C37: 0.92013889 | D37: 0.92638889 | E37: =ARRAY_CONSTRAIN(ARRAYFORMULA(G37+TIME(,OFFSET([2]Segment!$C$77,,$B37,),)), 1, 1) -> #ERROR! | F37: 2 | G37: =E37+TIME(,F37,) -> #ERROR! | H37: 0.93472222 | I37: 0.93888889 | J37: 0.94444444 | L37: Block Ends | V37: =W37-X37 -> 33 | W37: =(J37-C37)*1440 -> 35 | X37: =K37+F37+T37+P37 -> 2 | Y37: =X37/V37 -> 0.060606061 | Z37: =(J37-J36)*1440 -> 30
B38: Night | C38: 0.96180556 | D38: 0.96805556 | E38: =ARRAY_CONSTRAIN(ARRAYFORMULA(G38+TIME(,OFFSET([2]Segment!$C$77,,$B38,),)), 1, 1) -> #ERROR! | F38: 2 | G38: =E38+TIME(,F38,) -> #ERROR! | H38: 0.97638889 | I38: 0.98055556 | J38: 0.98611111 | L38: Block Ends | V38: =W38-X38 -> 33 | W38: =(J38-C38)*1440 -> 35 | X38: =K38+F38+T38+P38 -> 2 | Y38: =X38/V38 -> 0.060606061 | Z38: =(J38-J37)*1440 -> 60
F39: =SUM(F7:F38) -> 64 | K39: =SUM(K7:K38) -> 202 | P39: =SUM(P7:P38) -> 60 | S39: Service Hours | V39: =SUM(V5:V38)/60 -> 37.983333 | W39: =SUM(W5:W38)/60 -> 48.283333 | X39: =SUM(X5:X38)/60 -> 10.3 | Y39: =X39/V39 -> 0.27117157
S41: Service Hours
A42: Saturday
C43: Route 2A | L43: Route 2B
C44: DEPART | E44: ARRIVE | G44: DEPART | J44: ARRIVE | L44: DEPART | O44: ARRIVE | Q44: DEPART | S44: ARRIVE | U44: DEPART
B45: Stop Name | C45: Park Place | D45: Veteran's at Essa | E45: =E3 -> Cuthbert Street | G45: =G3 -> Cuthbert Street | H45: Sproule at Kraus | I45: Dunlop at Ferndale | J45: Downtown | L45: Downtown | M45: Ferndale Drive | N45: Sproule at Kraus | O45: =O3 -> Ferndale Woods Public School | Q45: =Q3 -> Ferndale Woods Public School | R45: Veteran's at Essa | S45: Park Place | U45: Park Place
B46: Stop ID | C46: 777 | D46: 662 | E46: =E4 -> 829 | F46: R | G46: =G4 -> 829 | H46: 627 | I46: 271 | J46: 1 | K46: R | L46: 1 | M46: 893 | N46: 626 | O46: =O4 -> 841 | P46: R | Q46: =Q4 -> 841 | R46: 847 | S46: 777 | T46: R | U46: 777 | V46: Travel Time | W46: Cycle Time | X46: R | Y46: R Ratio | Z46: Frequency | AD46: Headway Management
B47: Early Morning | H47: 0.26805556 | I47: 0.27222222 | J47: 0.27777778 | K47: 8 | L47: 0.28333333 | M47: 0.28819444 | N47: 0.29305556 | O47: =ARRAY_CONSTRAIN(ARRAYFORMULA(Q47+TIME(,OFFSET([2]Segment!$C$83,,$B47,),)), 1, 1) -> #ERROR! | P47: 2 | Q47: =O47+TIME(,P47,) -> #ERROR! | R47: 0.30277778 | S47: 0.30972222 | T47: 9 | U47: 0.31597222 | V47: =W47-X47 -> 50 | W47: =(U47-H47)*1440 -> 69 | X47: =K47+F47+T47+P47 -> 19 | Y47: =X47/V47 -> 0.38 | AD47: DT Connection
B48: Early Morning | H48: 0.28888889 | I48: 0.29305556 | J48: 0.29861111 | K48: 8 | L48: 0.30416667 | M48: 0.30902778 | N48: 0.31388889 | O48: =ARRAY_CONSTRAIN(ARRAYFORMULA(Q48+TIME(,OFFSET([2]Segment!$C$83,,$B48,),)), 1, 1) -> #ERROR! | P48: 2 | Q48: =O48+TIME(,P48,) -> #ERROR! | R48: 0.32361111 | S48: 0.33055556 | T48: 9 | U48: 0.33680556 | V48: =W48-X48 -> 50 | W48: =(U48-H48)*1440 -> 69 | X48: =K48+F48+T48+P48 -> 19 | Y48: =X48/V48 -> 0.38 | Z48: =(U48-U47)*1440 -> 30 | AD48: 400 Connection
B49: Morning | C49: 0.29513889 | D49: 0.30138889 | E49: =ARRAY_CONSTRAIN(ARRAYFORMULA(G49+TIME(,OFFSET([2]Segment!$C$77,,$B49,),)), 1, 1) -> #ERROR! | F49: 2 | G49: =E49+TIME(,F49,) -> #ERROR! | H49: 0.30972222 | I49: 0.31388889 | J49: 0.31944444 | K49: 8 | L49: 0.325 | M49: 0.32986111 | N49: 0.33472222 | O49: =ARRAY_CONSTRAIN(ARRAYFORMULA(Q49+TIME(,OFFSET([2]Segment!$C$83,,$B49,),)), 1, 1) -> #ERROR! | P49: 2 | Q49: =O49+TIME(,P49,) -> #ERROR! | R49: 0.34444444 | S49: 0.35138889 | T49: 9 | U49: 0.35763889 | V49: =W49-X49 -> 69 | W49: =(U49-C49)*1440 -> 90 | X49: =K49+F49+T49+P49 -> 21 | Y49: =X49/V49 -> 0.30434783 | Z49: =(U49-U48)*1440 -> 30 | AD49: GC Connection
...

Sheet 7
A1: Weekday | C1: 7A | O1: 7B
C2: DEPART | D2: ARRIVE | E2: R | F2: DEPART | G2: ARRIVE | H2: R | I2: DEPART | J2: ARRIVE | K2: R | L2: DEPART | N2: ARRIVE | O2: R | P2: DEPART | Q2: ARRIVE | R2: R | S2: DEPART | T2: ARRIVE | U2: R | V2: DEPART | X2: R | Y2: DEPART | Z2: ARRIVE | AA2: R | AB2: DEPART
B3: Stop Name | C3: Park Place | D3: Peggy Hill Community Centre | F3: Peggy Hill Community Centre | G3: Allandale GO Station | I3: Allandale GO Station | J3: Downtown | L3: Downtown | M3: Georgian College | N3: Rose Street | P3: Rose Street | Q3: Downtown | S3: Downtown | T3: Allandale GO Station | V3: Allandale GO Station | W3: Peggy Hill Community Centre | Y3: Peggy Hill Community Centre | Z3: Park Place | AB3: Park Place
B4: Stop ID | C4: 777 | D4: 487 | F4: 487 | G4: 732 | I4: 732 | J4: 1 | L4: 1 | M4: 330 | N4: 251 | P4: 251 | Q4: 1 | S4: 1 | T4: 732 | V4: 732 | W4: 488 | Y4: 487 | Z4: 777 | AB4: 777 | AC4: Travel Time | AD4: Cycle Time | AE4: R | AF4: R Ratio (15% Target) | AG4: Frequency
B5: Early Morning | M5: 0.22847222 | N5: 0.22986111 | O5: 2 | P5: 0.23125 | Q5: 0.23680556 | R5: 4 | S5: 0.23958333 | T5: 0.24375 | U5: 3 | V5: 0.24583333 | W5: 0.25763889 | X5: 0 | Y5: 0.25763889 | Z5: 0.26875 | AA5: 6 | AB5: 0.27291667 | AC5: =AD5-AE5 -> 49 | AD5: =(AB5-M5)*1440 -> 64 | AE5: =U5+R5+O5+K5+AA5+E5+H5+X5 -> 15 | AF5: =AE5/AC5 -> 0.30612245 | AI5: Headway Management
B6: Early Morning | M6: 0.24930556 | N6: 0.25069444 | O6: 2 | P6: 0.25208333 | Q6: 0.25763889 | R6: 3 | S6: 0.25972222 | T6: 0.26388889 | U6: 2 | V6: 0.26527778 | W6: 0.27708333 | X6: 0 | Y6: 0.27708333 | Z6: 0.28819444 | AB6: 0.28819444 | AC6: =AD6-AE6 -> 49 | AD6: =(AB6-M6)*1440 -> 56 | AE6: =U6+R6+O6+K6+AA6+E6+H6+X6 -> 7 | AF6: =AE6/AC6 -> 0.14285714 | AG6: =(AB6-AB5)*1440 -> 22 | AI6: Dt Connection
B7: Early Morning | C7: 0.23125 | D7: 0.24236111 | E7: 0 | F7: 0.24236111 | G7: 0.25416667 | H7: 3 | I7: 0.25625 | J7: 0.25972222 | K7: 3 | L7: 0.26180556 | M7: 0.26944444 | N7: 0.27083333 | O7: 2 | P7: 0.27222222 | Q7: 0.27777778 | R7: 5 | S7: 0.28125 | T7: 0.28541667 | U7: 3 | V7: 0.2875 | W7: 0.29930556 | X7: 0 | Y7: 0.29930556 | Z7: 0.31041667 | AA7: 3 | AB7: 0.3125 | AC7: =AD7-AE7 -> 98 | AD7: =(AB7-C7)*1440 -> 117 | AE7: =U7+R7+O7+K7+AA7+E7+H7+X7 -> 19 | AF7: =AE7/AC7 -> 0.19387755 | AG7: =(AB7-AB6)*1440 -> 35 | AI7: 400 Connection
